<?xml version="1.0" ?>
<mujoco>
  <asset>
    <texture name="grid" type="2d" builtin="checker" width="512" height="512" rgb1=".1 .2 .3" rgb2=".2 .3 .4"/>
    <material name="grid" texture="grid" texrepeat="1 1" texuniform="true" reflectance=".2"/>
    <mesh name="chasis" scale=".1 .06 .015"
      vertex=" 9   2   0
              -10  10  10
               9  -2   0
               10  3  -10
               10 -3  -10
              -8   10 -10
              -10 -10  10
              -8  -10 -10
              -5   0   20"/>
  </asset>
    
  <default>
    <joint damping=".005" actuatorfrcrange="-1000 1000"/> <!-- Reduced damping, increased actuatorfrcrange -->
    <default class="wheel">
      <geom type="cylinder" size=".2 .05" rgba=".5 .5 1 1" friction="0.01"/> <!-- Adjusted wheel size and friction -->
    </default>
    <default class="decor">
      <site type="box" rgba=".5 1 .5 1"/>
    </default>
  </default>


    
  <worldbody>
    <!-- Define the floor -->
    <body name="floor" pos="10 10 0">
        <geom name="floor_geom" type="plane" size="50 50 1" rgba="0.5 0.5 0.5 1"/>
    </body>

    <!-- Define the agent -->
    <body name="car" pos="-12 -13 0.5">
      <freejoint/>
      <light name="top light" pos="0 0 2" mode="trackcom" diffuse=".4 .4 .4"/>
      <geom name="chasis" type="mesh" mesh="chasis"/>
      <geom name="front wheel" pos=".8 0 -.15" type="sphere" size=".15" condim="1" priority="1"/>
      <light name="front light" pos="1 0 .2" dir="2 0 -1" diffuse="1 1 1"/>
      <body name="left wheel" pos="-.7 .6 0" zaxis="0 1 0">
        <joint name="left"/>
        <geom class="wheel"/>
        <site class="decor" size=".06 .25 .12"/>
        <site class="decor" size=".25 .06 .12"/>
      </body>
      <body name="right wheel" pos="-.7 -.6 0" zaxis="0 1 0">
        <joint name="right"/>
        <geom class="wheel"/>
        <site class="decor" size=".06 .25 .12"/>
        <site class="decor" size=".25 .06 .12"/>
      </body>
    </body>

    <!-- Define the destination -->
    <body name="destination" pos="27 27 0.5">
      <!-- Base of the robot -->
      <geom name="destination_base" type="cylinder" size="0.5 0.5" pos="0 0 0.3" rgba="0.8 0.8 0.8 1"/>
      
      <!-- Body of the robot -->
      <geom name="destination_body" type="box" size="0.35 0.35 0.5" pos="0 0 0.65" rgba="0.9 0.6 0.6 1"/>
      
      <!-- Head of the robot -->
      <geom name="destination_head" type="sphere" size="0.25" pos="0 0 1.1" rgba="0.9 0.6 0.6 1"/>
      
      <!-- Eyes of the robot -->
      <geom name="destination_left_eye" type="sphere" size="0.05" pos="-0.1 0.1 1.2" rgba="0.1 0.1 0.1 1"/>
      <geom name="destination_right_eye" type="sphere" size="0.05" pos="0.1 0.1 1.2" rgba="0.1 0.1 0.1 1"/>
      
      <!-- Eyebrows -->
      <geom name="destination_left_eyebrow" type="box" size="0.07 0.02 0.01" pos="-0.1 0.13 1.25" rgba="0.2 0.1 0.1 1"/>
      <geom name="destination_right_eyebrow" type="box" size="0.07 0.02 0.01" pos="0.1 0.13 1.25" rgba="0.2 0.1 0.1 1"/>
      
      <!-- Mouth -->
      <geom name="destination_mouth" type="box" size="0.1 0.02 0.01" pos="0 0.1 1.05" rgba="0.2 0.1 0.1 1"/>
      
      <!-- Hair (simple box as a placeholder for hair) -->
      <geom name="destination_hair" type="box" size="0.3 0.1 0.1" pos="0 0 1.3" rgba="0.3 0.1 0.1 1"/>
      
      <!-- Left arm -->
      <geom name="destination_left_arm" type="box" size="0.1 0.35 0.1" pos="-0.45 0 0.7" rgba="0.9 0.6 0.6 1"/>
      
      <!-- Right arm -->
      <geom name="destination_right_arm" type="box" size="0.1 0.35 0.1" pos="0.45 0 0.7" rgba="0.9 0.6 0.6 1"/>
      
      <!-- Left hand -->
      <geom name="destination_left_hand" type="box" size="0.05 0.05 0.02" pos="-0.45 0 0.35" rgba="0.9 0.6 0.6 1"/>
      
      <!-- Right hand -->
      <geom name="destination_right_hand" type="box" size="0.05 0.05 0.02" pos="0.45 0 0.35" rgba="0.9 0.6 0.6 1"/>
      
      <!-- Left leg -->
      <geom name="destination_left_leg" type="box" size="0.1 0.1 0.4" pos="-0.2 0 -0.4" rgba="0.9 0.6 0.6 1"/>
      
      <!-- Right leg -->
      <geom name="destination_right_leg" type="box" size="0.1 0.1 0.4" pos="0.2 0 -0.4" rgba="0.9 0.6 0.6 1"/>
      
      <!-- Left foot -->
      <geom name="destination_left_foot" type="box" size="0.1 0.05 0.02" pos="-0.2 0 -0.55" rgba="0.9 0.6 0.6 1"/>
      
      <!-- Right foot -->
      <geom name="destination_right_foot" type="box" size="0.1 0.05 0.02" pos="0.2 0 -0.55" rgba="0.9 0.6 0.6 1"/>
      
      <!-- Additional features -->
      <!-- Nose -->
      <geom name="destination_nose" type="sphere" size="0.05" pos="0 0.1 1.1" rgba="0.9 0.6 0.6 1"/>
      
      <!-- Decorative elements -->
      <geom name="destination_decoration" type="box" size="0.05 0.05 0.02" pos="0 0.15 1.2" rgba="1 0.5 0.5 1"/>
    </body>
  </worldbody>

  <tendon>
      <fixed name="forward">
          <joint joint="left" coef="200.0"/>  <!-- Increased coefficient -->
          <joint joint="right" coef="200.0"/> <!-- Increased coefficient -->
      </fixed>
      <fixed name="turn">
          <joint joint="left" coef="-2.0"/> <!-- Increased coefficient -->
          <joint joint="right" coef="2.0"/>  <!-- Increased coefficient -->
      </fixed>
  </tendon>


  <actuator>
      <motor name="forward" tendon="forward" ctrlrange="-10 10"/> <!-- Increased from -2 2 to -10 10 -->
      <motor name="turn" tendon="turn" ctrlrange="-100 100"/> <!-- Increased from -2 2 to -10 10 -->
  </actuator>


  <sensor>
    <jointactuatorfrc name="right" joint="right"/>
    <jointactuatorfrc name="left" joint="left"/>
  </sensor>



    
</mujoco>
